Workbook

Sheet probabilities
A1: population | B1: DAG | C1: node | D1: outcome | E1: best | F1: lower | G1: upper | H1: condition1 | I1: value1 | J1: condition2 | K1: value2 | L1: condition3 | M1: value3 | N1: condition4 | O1: value4 | P1: condition5 | Q1: value5 | R1: Notes
A2: PWID_opioid | B2: injection_overdose_opioid | C2: int_safesupply | D2: none | E2: 1 | F2: 1 | G2: 1
A3: PWID_opioid | B3: injection_overdose_opioid | C3: int_safesupply | D3: safesupply | E3: 0 | F3: 0 | G3: 0 | R3: Prospective intervention
A4: PWID_opioid | B4: injection_overdose_opioid | C4: int_check | D4: none | E4: 0.95300825 | F4: 0.93421155 | G4: 0.97180495
A5: PWID_opioid | B5: injection_overdose_opioid | C5: int_check | D5: check | E5: 0.04699175 | F5: 0.02819505 | G5: 0.06578845 | R5: Numerator: based on CanTEST number of unique IDs, assuming 76.1% people from ACT (personal communication) and 2% for heroin (CanTEST 2023 evaluation, proportion of clientele who provided heroin for testing), plus assuming 5 people covered for each person reached (in place of 2 under standard conditions). Denominator: population of PWID-opioids.
A6: PWID_opioid | B6: injection_overdose_opioid | C6: int_oat | D6: none | E6: 0.57 | F6: 0.47 | G6: 0.67
A7: PWID_opioid | B7: injection_overdose_opioid | C7: int_oat | D7: oat | E7: 0.43 | F7: 0.33 | G7: 0.53 | R7: Report methadone or buprenorphinedrug treatment. Source: IDRS ACT 2023, table 7
A8: PWID_opioid | B8: injection_overdose_opioid | C8: int_nal | D8: none | E8: 0.32 | F8: 0.22 | G8: 0.42
A9: PWID_opioid | B9: injection_overdose_opioid | C9: int_nal | D9: naloxone | E9: 0.68 | F9: 0.58 | G9: 0.78 | R9: 68% PWID accessed in past year. Source: IDRS ACT, pg 60.
A10: PWID_opioid | B10: injection_overdose_opioid | C10: int_dcr | D10: none | E10: 1 | F10: 1 | G10: 1
A11: PWID_opioid | B11: injection_overdose_opioid | C11: int_dcr | D11: medicalised | E11: 0 | F11: 0 | G11: 0 | R11: prospective intervention
A12: PWID_opioid | B12: injection_overdose_opioid | C12: int_dcr | D12: peerled | E12: 0 | F12: 0 | G12: 0 | R12: prospective intervention
A13: PWID_opioid | B13: injection_overdose_opioid | C13: int_techno | D13: none | E13: 1 | F13: 1 | G13: 1 | R13: prospective intervention
A14: PWID_opioid | B14: injection_overdose_opioid | C14: int_techno | D14: techno | E14: 0 | F14: 0 | G14: 0 | R14: prospective intervention
A15: PWID_opioid | B15: injection_overdose_opioid | C15: drug_id | D15: yes | E15: 0 | F15: 0 | G15: 0 | H15: int_check | I15: none | R15: Assume unexpected drugs can only be identified with drug checking in place
A16: PWID_opioid | B16: injection_overdose_opioid | C16: drug_id | D16: yes | E16: 0.504 | F16: 0.304 | G16: 0.704 | H16: int_check | I16: check | R16: Assumed increased by 20% in line with increase in overdose risk. Unexpected drug identifed or inconclusive result (CanTEST 2023 evaluation pg 45; +- 0.2 CI added)
A17: PWID_opioid | B17: injection_overdose_opioid | C17: behavchange | D17: yes | E17: 0.52 | F17: 0.42 | G17: 0.62 | H17: drug_id | I17: yes | R17: Based on CanTEST intention to not use drug, plus half of those who were undecided (CanTEST 2023 evaluation; +-0.1 CI added)
A18: PWID_opioid | B18: injection_overdose_opioid | C18: behavchange | D18: yes | E18: 0 | F18: 0 | G18: 0 | H18: drug_id | I18: no | R18: Assume that if do not receive abnormal results, will not change behaviour
A19: PWID_opioid | B19: injection_overdose_opioid | C19: inj_loc | D19: dcr | E19: 0 | F19: 0 | G19: 0 | H19: int_dcr | I19: none | R19: prospective intervention
A20: PWID_opioid | B20: injection_overdose_opioid | C20: inj_loc | D20: public | E20: 0.14 | F20: 0.04 | G20: 0.24 | H20: int_dcr | I20: none | R20: Same as baseline, when no DCR available. Source: IDRS ACT 2023, table 5; +-0.1 CI added
A21: PWID_opioid | B21: injection_overdose_opioid | C21: inj_loc | D21: private | E21: 0.86 | F21: 0.76 | G21: 0.96 | H21: int_dcr | I21: none | R21: Same as baseline, when no DCR available. Source: IDRS ACT 2023, table 5; +-0.1 CI added
A22: PWID_opioid | B22: injection_overdose_opioid | C22: inj_loc | D22: dcr | E22: 0.3125 | F22: 0.2125 | G22: 0.4125 | H22: int_dcr | I22: medicalised | R22: Among those who attended Melbourne MSIR at all, % who reported frequent use (>50% of injections). Source: Van Den Boom (2021). +-0.1 CI added
A23: PWID_opioid | B23: injection_overdose_opioid | C23: inj_loc | D23: public | E23: 0.06 | F23: 0.028 | G23: 0.122 | H23: int_dcr | I23: medicalised | R23: Based on OR = 0.39 (0.18-0.85) for reduction in public infection. Source: Folch 2018, calculated from baseline with no DCR
A24: PWID_opioid | B24: injection_overdose_opioid | C24: inj_loc | D24: private | E24: 0.6275 | F24: 0.4655 | G24: 0.7595 | H24: int_dcr | I24: medicalised | R24: 1 - sum(DCR + public injections)
A25: PWID_opioid | B25: injection_overdose_opioid | C25: inj_loc | D25: dcr | E25: 0.3125 | F25: 0.2125 | G25: 0.4125 | H25: int_dcr | I25: peerled | R25: Among those who attended Melbourne MSIR at all, % who reported frequent use (>50% of injections). Source: Van Den Boom (2021). +-0.1 CI added
A26: PWID_opioid | B26: injection_overdose_opioid | C26: inj_loc | D26: public | E26: 0.06 | F26: 0.028 | G26: 0.122 | H26: int_dcr | I26: peerled | R26: Based on OR = 0.39 (0.18-0.85) for reduction in public infection. Source: Folch 2018, calculated from baseline with no DCR
A27: PWID_opioid | B27: injection_overdose_opioid | C27: inj_loc | D27: private | E27: 0.6275 | F27: 0.4655 | G27: 0.7595 | H27: int_dcr | I27: peerled | R27: 1 - sum(DCR + public injections)
A28: PWID_opioid | B28: injection_overdose_opioid | C28: might_overdose_inj_opioid | D28: yes | E28: 0.24508719 | F28: 0.22482138 | G28: 0.25987112 | H28: int_oat | I28: none | J28: int_safesupply | K28: none | R28: Assumes 20% increase in baseline rate of overdose. Estimated based on current prevalence of opioid overdose, baseline coverage of interventions, and effect size for OAT and safer opioid supply.
A29: PWID_opioid | B29: injection_overdose_opioid | C29: might_overdose_inj_opioid | D29: yes | E29: 0.051468309 | F29: 0.02922678 | G29: 0.088356182 | H29: int_oat | I29: oat | J29: int_safesupply | K29: none | R29: Assumes 20% increase in baseline rate of overdose. Estimated based on current prevalence of opioid overdose, baseline coverage of interventions, and effect size for OAT and safer opioid supply.
A30: PWID_opioid | B30: injection_overdose_opioid | C30: might_overdose_inj_opioid | D30: yes | E30: 0.095584003 | F30: 0.065198202 | G30: 0.12733685 | H30: int_oat | I30: none | J30: int_safesupply | K30: safesupply | R30: Assumes 20% increase in baseline rate of overdose. Estimated based on current prevalence of opioid overdose, baseline coverage of interventions, and effect size for OAT and safer opioid supply.
A31: PWID_opioid | B31: injection_overdose_opioid | C31: might_overdose_inj_opioid | D31: yes | E31: 0.020072641 | F31: 0.0084757662 | G31: 0.043294529 | H31: int_oat | I31: oat | J31: int_safesupply | K31: safesupply | R31: Modelled combination of interventions were implemented such that OAT and SOS were not scaled up together due to overlapping function. Assumes 20% increase in baseline rate of overdose.
A32: PWID_opioid | B32: injection_overdose_opioid | C32: overdose_inj_opioid | D32: yes | E32: 0.745 | F32: 0.5 | G32: 0.99 | H32: behavchange | I32: yes | J32: might_overdose_inj_opioid | K32: yes | R32: Assumed that behaviour change further reduced the risk of overdose by 0.745 (95% CI 0.5-0.99) in addition to impact of OAT or safer opioid supply.
A33: PWID_opioid | B33: injection_overdose_opioid | C33: overdose_inj_opioid | D33: yes | E33: 1 | F33: 1 | G33: 1 | H33: behavchange | I33: no | J33: might_overdose_inj_opioid | K33: yes | R33: Assumed that behaviour change further reduced the risk of overdose by 0.745 (95% CI 0.5-0.99) in addition to impact of OAT or safer opioid supply.
A34: PWID_opioid | B34: injection_overdose_opioid | C34: overdose_inj_opioid | D34: yes | E34: 0 | F34: 0 | G34: 0 | H34: behavchange | I34: yes | J34: might_overdose_inj_opioid | K34: no
A35: PWID_opioid | B35: injection_overdose_opioid | C35: overdose_inj_opioid | D35: yes | E35: 0 | F35: 0 | G35: 0 | H35: behavchange | I35: no | J35: might_overdose_inj_opioid | K35: no
A36: PWID_opioid | B36: injection_overdose_opioid | C36: nal_avail | D36: yes | E36: 1 | F36: 1 | G36: 1 | H36: inj_loc | I36: dcr | J36: int_nal | K36: none | R36: Naloxone available in DCR independent of THN program
A37: PWID_opioid | B37: injection_overdose_opioid | C37: nal_avail | D37: yes | E37: 0 | F37: 0 | G37: 0 | H37: inj_loc | I37: public | J37: int_nal | K37: none | R37: Assume if no THN intervention, no access to naloxone in community
A38: PWID_opioid | B38: injection_overdose_opioid | C38: nal_avail | D38: yes | E38: 0 | F38: 0 | G38: 0 | H38: inj_loc | I38: private | J38: int_nal | K38: none | R38: Assume if no THN intervention, no access to naloxone in community
A39: PWID_opioid | B39: injection_overdose_opioid | C39: nal_avail | D39: yes | E39: 1 | F39: 1 | G39: 1 | H39: inj_loc | I39: dcr | J39: int_nal | K39: naloxone | R39: Naloxone available in DCR independent of THN program
A40: PWID_opioid | B40: injection_overdose_opioid | C40: nal_avail | D40: yes | E40: 0.615 | F40: 0.52 | G40: 0.71 | H40: inj_loc | I40: public | J40: int_nal | K40: naloxone | R40: Among those who have received naloxone, 52-71% often or always have naloxone on hand when using opioids. Source: IDRS ACT 2023
...

Sheet evidence
A1: population | B1: DAG | C1: node | D1: outcome | E1: baseline | F1: Source and notes
A2: PWID_opioid | B2: injection_overdose_opioid | C2: drug_id | D2: yes | F2: Defined in probabilities
A3: PWID_opioid | B3: injection_overdose_opioid | C3: behavchange | D3: yes | E3: =AVERAGE(0.32,0.32+0.4) -> 0.52 | F3: Based on CanTEST intention to not use drug, plus half of those who were undecided
A4: PWID_opioid | B4: injection_overdose_opioid | C4: inj_loc | D4: dcr | F4: Defined in probabilities
A5: PWID_opioid | B5: injection_overdose_opioid | C5: inj_loc | D5: public | F5: Defined in probabilities
A6: PWID_opioid | B6: injection_overdose_opioid | C6: inj_loc | D6: private | F6: Defined in probabilities
A7: PWID_opioid | B7: injection_overdose_opioid | C7: overdose_inj_opioid | D7: yes | E7: =13%+1/31.3*13% -> 0.13415335 | F7: IDRS ACT 2023, pg 59. 13% specific to non-fatal opioid overdose. Adjusted to include fatal overdoses, assuming 1 fatal overdose for every 31.3 non fatal overdoses (Darke 2003)
A8: PWID_opioid | B8: injection_overdose_opioid | C8: nal_avail | D8: yes | E8: =68%*(52%+19%) -> 0.4828 | F8: % who have accesed naloxone in past year * among those who have ever accessed naloxone , % who usually have on hand (52% always have on hand when use + 19% often). Source: IDRS ACT 2023, pg 60
A9: PWID_opioid | B9: injection_overdose_opioid | C9: nal_used | D9: yes | E9: =33%*50% -> 0.165 | F9: Based on reported % who have resuscitated someone with naloxone in past year. Source: IDRS ACT 2023, pg. 61
A10: PWID_opioid | B10: injection_overdose_opioid | C10: emergency_response_inj_opioid | D10: yes | E10: =71/population_size!B2 -> 0.058276742 | F10: Based on number of ambulance attendances for heroin divided by population size of PWID-opioids. Source: Alcohol, tobacco and other drugs in Australia 2024, Drug types, supplementary tables S2.10
A11: PWID_opioid | B11: injection_overdose_opioid | C11: death_inj_opioid | D11: yes | E11: =(29*12/21)/population_size!B2 -> 0.013601815 | F11: Based on total number of opioid-related deaths in 2022 (ACT, NIDIP 2003-2022) and using split of pharmaeutical to heroin deaths from ACT in 2018 (ABS 2019). Derived number of pharmaceutical opioid deaths in 2022 divided by populations size PWID opioid users. Source: https://www.abs.gov.au/articles/opioid-induced-deaths-australia
A12: PWID_meth | B12: injection_overdose_nonopioid | C12: drug_id | D12: yes | F12: Defined in probabilities
A13: PWID_meth | B13: injection_overdose_nonopioid | C13: behavchange | D13: yes | E13: =AVERAGE(0.32,0.32+0.4) -> 0.52 | F13: Based on CanTEST intention to not use drug, plus half of those who were undecided
A14: PWID_meth | B14: injection_overdose_nonopioid | C14: inj_loc | D14: dcr | F14: Defined in probabilities
A15: PWID_meth | B15: injection_overdose_nonopioid | C15: inj_loc | D15: public | F15: Defined in probabilities
A16: PWID_meth | B16: injection_overdose_nonopioid | C16: inj_loc | D16: private | F16: Defined in probabilities
A17: PWID_meth | B17: injection_overdose_nonopioid | C17: overdose_inj_nonopioid | D17: yes | E17: =0.17-0.13 -> 0.04 | F17: Total overdose minus opioid overdose, IDRS 2023
A18: PWID_meth | B18: injection_overdose_nonopioid | C18: nal_avail | D18: yes | E18: =(E8*700+0*300)/1000 -> 0.33796 | F18: Used same coverage as opioid users among those who use both heroin and methamphetamine, and assumed those who used methamphetamine only did not have it available
A19: PWID_meth | B19: injection_overdose_nonopioid | C19: nal_used | D19: yes | F19: Defined in probabilities
A20: PWID_meth | B20: injection_overdose_nonopioid | C20: emergency_response_inj_nonopioid | D20: yes | E20: =84/(population_size!B3+4400) -> 0.015447332 | F20: Based on number of ambulance attendances for methamphetamine divided by population size of PWID-methamphetamines + non-injecting methamphetamines. (Alcohol, tobacco and other drugs in Australia 2024, Drug types, supplementary tables S2.10)
A21: PWID_meth | B21: injection_overdose_nonopioid | C21: death_inj_nonopioid | D21: yes | E21: =(1.9/100000*466416)/(population_size!B3+4400) -> 0.0016296759 | F21: rate 1.9 deaths per 100,000 people for ATS (AIHW supplementary tables table, data by region, table1 ). Using adult population size of ACT, derived number of deaths, and divided this by population size of PWID_methamphetamines (n=1000) + people using methamphatimines through non-injecting routes (n=4400)
A22: PWID | B22: IRID | C22: inj_loc | D22: dcr | F22: Defined in probabilities
A23: PWID | B23: IRID | C23: inj_loc | D23: public | F23: Defined in probabilities
A24: PWID | B24: IRID | C24: inj_loc | D24: private | F24: Defined in probabilities
A25: PWID | B25: IRID | C25: reuse | D25: yes | E25: 0.26 | F25: 26% of NSP users (NSP survey) reuse (likely underestimation when considering all PWID)
A26: PWID | B26: IRID | C26: irid | D26: yes | E26: 0.28 | F26: Based on reporting any injection related issues (artery injection, nerve damage, thrombosis, infection/abcess, dirty hit). IDRS ACT 2023, pg 54
A27: PWID | B27: IRID | C27: irid_hospital | D27: none | E27: =1-E29 -> 0.9573
A28: PWID | B28: IRID | C28: irid_hospital | D28: short | E28: 0 | F28: based on referral from DCR, which doesn’t yet exist so model as 0.
A29: PWID | B29: IRID | C29: irid_hospital | D29: long | E29: =42.7/1000 -> 0.0427 | F29: based on crude incidence rate of 42.7 per 1000 PY for hospitalisation for any injection-related disease (Colledge-Frisby 2022) ( 29.9 per 1000PY for hospitalisation for SSTI specifically)
A30: PWID | B30: BBV | C30: inj_loc | D30: dcr | F30: Defined in probabilities
A31: PWID | B31: BBV | C31: inj_loc | D31: public | F31: Defined in probabilities
A32: PWID | B32: BBV | C32: inj_loc | D32: private | F32: Defined in probabilities
A33: PWID | B33: BBV | C33: bbv_inci | D33: yes | E33: 0.054 | F33: 5.4 per 100 PY (2016-21). Iversen 2023. doi: 10.1111/add.16113.
A34: PWID | B34: BBV | C34: bbv_treat | D34: none | E34: =1-E35 -> 0.48
A35: PWID | B35: BBV | C35: bbv_treat | D35: treat | E35: =AVERAGE(0.32,0.72) -> 0.52 | F35: range based on Grebely 2020 (review), Aung 2023. Excluding studies from prior to 2016
A36: noninjectdrug_opioid | B36: noninjectdrug_opioidoverdose | C36: drug_id | D36: yes | F36: Defined in probabilities
A37: noninjectdrug_opioid | B37: noninjectdrug_opioidoverdose | C37: behavchange | D37: yes | E37: =AVERAGE(0.32,0.32+0.4) -> 0.52 | F37: Based on CanTEST intention to not use drug, plus half of those who were undecided
A38: noninjectdrug_opioid | B38: noninjectdrug_opioidoverdose | C38: overdose_noninj_opioid | D38: yes | E38: 0.05 | F38: Nielsen 2022 - assumption used in previous modelling
A39: noninjectdrug_opioid | B39: noninjectdrug_opioidoverdose | C39: nal_avail | D39: yes | E39: =20%*(52%+19%) -> 0.142 | F39: % who have accesed naloxone in past year * among those who have ever access naloxone, 52% always have on hand when use; 19% often. Increase to account for accompanying people or bystanders having on hand. IDRS pg 60 Estimate 20% have accessed in past year (Nielsen, personal commuication, 29/11/2024)
A40: noninjectdrug_opioid | B40: noninjectdrug_opioidoverdose | C40: nal_used | D40: yes | F40: Defined in probabilities
...

Sheet population_size
A1: population_size | B1: 2024 | C1: 2025 | D1: 2026 | E1: 2027 | F1: 2028 | G1: 2029 | H1: 2030
A2: PWID_opioid | B2: 1218.3248 | C2: 1239.0693 | D2: 1261.074 | E2: 1284.6642 | F2: 1308.1818 | G2: 1331.1972 | H2: 1353.5588
A3: PWID_meth | B3: 1037.8322 | C3: 1055.5035 | D3: 1074.2482 | E3: 1094.3436 | F3: 1114.3771 | G3: 1133.9828 | H3: 1153.0315
A4: PWID | B4: 1519.2977 | C4: 1545.1668 | D4: 1572.6075 | E4: 1602.0254 | F4: 1631.3528 | G4: 1660.0538 | H4: 1687.9396
A5: noninjectdrug_opioid | B5: 3796.2822 | C5: 3860.9217 | D5: 3929.488 | E5: 4002.9948 | F5: 4076.2752 | G5: 4147.9908 | H5: 4217.6692
A6: noninjectdrug_nonopioid | B6: 30045.5 | C6: 30557.086 | D6: 31099.751 | E6: 31681.517 | F6: 32261.492 | G6: 32829.082 | H6: 33380.548

Sheet costs
A1: population | B1: DAG | C1: node | D1: outcome | E1: unit_cost | F1: setup_cost | G1: cost_weight | H1: Notes
A2: PWID_opioid | B2: injection_overdose_opioid | C2: int_safesupply | D2: none | E2: 0 | F2: 0 | G2: 1
A3: PWID_opioid | B3: injection_overdose_opioid | C3: int_safesupply | D3: safesupply | E3: =AVERAGE(4376.3,32820.8) -> 18598.55 | F3: 0 | G3: 1 | H3: Midpoint of range: Canadian trial-based economic evaluation (SALOME), Canadian safer supply program evaluation (Gomes 2022)
A4: PWID_opioid | B4: injection_overdose_opioid | C4: int_check | D4: none | E4: 0 | F4: 0 | G4: 0
A5: PWID_opioid | B5: injection_overdose_opioid | C5: int_check | D5: check | E5: =383.1*2/5 -> 153.24 | F5: 0 | G5: 0 | H5: Cost per service user based on CanTEST 2023-24 data and assuming 5 people covered for each person reached
A6: PWID_opioid | B6: injection_overdose_opioid | C6: int_oat | D6: none | E6: 0 | F6: 0 | G6: 1
A7: PWID_opioid | B7: injection_overdose_opioid | C7: int_oat | D7: oat | E7: 5559.7 | F7: 0 | G7: 1 | H7: Annual cost per OAT patient. Source: Australian trial-based economic evaluation (Doran 2003)
A8: PWID_opioid | B8: injection_overdose_opioid | C8: int_nal | D8: none | E8: 0 | F8: 0 | G8: 1
A9: PWID_opioid | B9: injection_overdose_opioid | C9: int_nal | D9: naloxone | E9: 165.2 | F9: 0 | G9: 1 | H9: midpoint of range given commodity only and top-down estimate from CAHMA 2021-22 budget including training and distribution costs. Annualised cost adjusted based on assumption of refill every 2 years
A10: PWID_opioid | B10: injection_overdose_opioid | C10: int_dcr | D10: none | E10: 0 | F10: 0 | G10: 0
A11: PWID_opioid | B11: injection_overdose_opioid | C11: int_dcr | D11: medicalised | E11: =50.4*108 -> 5443.2 | F11: 2271418.1 | G11: 0 | H11: Cost per supervised injection adjusted based on 238 injections per year, assuming 108 are covered in DRC
A12: PWID_opioid | B12: injection_overdose_opioid | C12: int_dcr | D12: peerled | E12: =40.3*108 -> 4352.4 | F12: 2271418.1 | G12: 0 | H12: Cost per supervised injection adjusted based on 238 injections per year, assuming 108 are covered in DRC
A13: PWID_opioid | B13: injection_overdose_opioid | C13: int_techno | D13: none | E13: 0 | F13: 0 | G13: 1
A14: PWID_opioid | B14: injection_overdose_opioid | C14: int_techno | D14: techno | E14: 2740.7248 | F14: 0 | G14: 1 | H14: Upper limit: estimated cost for hotline based on 5 FTE nurses at maximum coverage, assuming 50% of injections are covered. Lower limit: assuming 50,000 in start up costs divided by 300 PY covered at scale up
A15: PWID_opioid | B15: injection_overdose_opioid | C15: drug_id | D15: yes | E15: 0 | F15: 0 | G15: 1
A16: PWID_opioid | B16: injection_overdose_opioid | C16: drug_id | D16: no | E16: 0 | F16: 0 | G16: 1
A17: PWID_opioid | B17: injection_overdose_opioid | C17: behavchange | D17: yes | E17: 0 | F17: 0 | G17: 1
A18: PWID_opioid | B18: injection_overdose_opioid | C18: behavchange | D18: no | E18: 0 | F18: 0 | G18: 1
A19: PWID_opioid | B19: injection_overdose_opioid | C19: inj_loc | D19: dcr | E19: 0 | F19: 0 | G19: 1
A20: PWID_opioid | B20: injection_overdose_opioid | C20: inj_loc | D20: public | E20: 0 | F20: 0 | G20: 1
A21: PWID_opioid | B21: injection_overdose_opioid | C21: inj_loc | D21: private | E21: 0 | F21: 0 | G21: 1
A22: PWID_opioid | B22: injection_overdose_opioid | C22: overdose_inj_opioid | D22: yes | E22: 0 | F22: 0 | G22: 1
A23: PWID_opioid | B23: injection_overdose_opioid | C23: overdose_inj_opioid | D23: no | E23: 0 | F23: 0 | G23: 1
A24: PWID_opioid | B24: injection_overdose_opioid | C24: nal_avail | D24: yes | E24: 0 | F24: 0 | G24: 1
A25: PWID_opioid | B25: injection_overdose_opioid | C25: nal_avail | D25: no | E25: 0 | F25: 0 | G25: 1
A26: PWID_opioid | B26: injection_overdose_opioid | C26: nal_used | D26: yes | E26: 0 | F26: 0 | G26: 1
A27: PWID_opioid | B27: injection_overdose_opioid | C27: nal_used | D27: no | E27: 0 | F27: 0 | G27: 1
A28: PWID_opioid | B28: injection_overdose_opioid | C28: emergency_response_inj_opioid | D28: yes | E28: 1147 | F28: 0 | G28: 1 | H28: Expenditure for ACT ambulance services in 2022-23 ($87,488,000) divided by the total number of ambulance responses (65,715). Adjusted for the proportion of ACT ambulance revenue that is from government funding (86.1%). Report on Government Services 2024 ((https://www.pc.gov.au/ongoing/report-on-government-services/2024/data-downloads)
A29: PWID_opioid | B29: injection_overdose_opioid | C29: emergency_response_inj_opioid | D29: no | E29: 0 | F29: 0 | G29: 1
A30: PWID_opioid | B30: injection_overdose_opioid | C30: death_inj_opioid | D30: yes | E30: 3658792.2 | F30: 0 | G30: 1 | H30: Value of a statistical life year (source: The Office of Impact Analysis, Department of the Prime Minister and Cabinet; 2024 [cited 2024 Dec 3]. Available from: https://oia.pmc.gov.au/resources/guidance-assessing-impacts/value-statistical-life) converted to years of life lost based on the age and sex distribution of overdose deaths and age- and sex-specific expected years of remaining life from ABS mortality rate medium projections, adjusted for additional drug-related mortality.
A31: PWID_opioid | B31: injection_overdose_opioid | C31: death_inj_opioid | D31: no | E31: 0 | F31: 0 | G31: 1
A32: PWID_meth | B32: injection_overdose_nonopioid | C32: int_check | D32: none | E32: 0 | F32: 0 | G32: 0
A33: PWID_meth | B33: injection_overdose_nonopioid | C33: int_check | D33: check | E33: =383.1*2/5 -> 153.24 | F33: 0 | G33: 0 | H33: Cost per service user based on CanTEST 2023-24 data and assuming 5 people covered for each person reached
A34: PWID_meth | B34: injection_overdose_nonopioid | C34: int_nal | D34: none | E34: 0 | F34: 0 | G34: 0
A35: PWID_meth | B35: injection_overdose_nonopioid | C35: int_nal | D35: naloxone | E35: 165.2 | F35: 0 | G35: 0 | H35: Cost per service user based on CanTEST 2023-24 data and assuming 2 people covered for each person reached
A36: PWID_meth | B36: injection_overdose_nonopioid | C36: int_dcr | D36: none | E36: 0 | F36: 0 | G36: 0
A37: PWID_meth | B37: injection_overdose_nonopioid | C37: int_dcr | D37: medicalised | E37: =50.4*108 -> 5443.2 | F37: 2271418.1 | G37: 0 | H37: midpoint of range given commodity only and top-down estimate from CAHMA 2021-22 budget including training and distribution costs. Annualised cost adjusted based on assumption of refill every 2 years
A38: PWID_meth | B38: injection_overdose_nonopioid | C38: int_dcr | D38: peerled | E38: =40.3*108 -> 4352.4 | F38: 2271418.1 | G38: 0
A39: PWID_meth | B39: injection_overdose_nonopioid | C39: int_techno | D39: none | E39: 0 | F39: 0 | G39: 0 | H39: Cost per supervised injection adjusted based on 238 injections per year, assuming 108 are covered in DRC
A40: PWID_meth | B40: injection_overdose_nonopioid | C40: int_techno | D40: techno | E40: 2740.7248 | F40: 0 | G40: 0 | H40: Cost per supervised injection adjusted based on 238 injections per year, assuming 108 are covered in DRC
...

Sheet max_coverage
A1: population | B1: DAG | C1: node | D1: outcome | E1: max_coverage | F1: notes
A2: PWID_opioid | B2: injection_overdose_opioid | C2: int_safesupply | D2: safesupply | E2: 0.4047 | F2: Based on proportion who aren't currently on OAT and the proportion of PWID who have recently used opioids with probable opioid dependence
A3: PWID_opioid | B3: injection_overdose_opioid | C3: int_check | D3: check | E3: 0.1 | F3: Assume could reach higher % if overdose risk increase
A4: PWID_opioid | B4: injection_overdose_opioid | C4: int_oat | D4: oat | E4: 0.639 | F4: Based on 90% of those with probable opioid dependence
A5: PWID_opioid | B5: injection_overdose_opioid | C5: int_nal | D5: naloxone | E5: 0.9 | F5: WHO target
A6: PWID_opioid | B6: injection_overdose_opioid | C6: int_dcr | D6: medicalised | E6: 0.3 | F6: Assumption. Alternative: based on IDRS, 13% melbourne sample and 10% of sydney sample last injected at DCR (National IDRS 2023)
A7: PWID_opioid | B7: injection_overdose_opioid | C7: int_dcr | D7: peerled | E7: 0.6 | F7: Assume can reach double coverage
A8: PWID_opioid | B8: injection_overdose_opioid | C8: int_techno | D8: techno | E8: 0.186 | F8: Based on % who used alone at last injection (IDRS ACT 2023, data request received 3/12/2024) and assuming 40% acceptability (double the acceptability due to increase in overdose risk and awareness)
A9: PWID_meth | B9: injection_overdose_nonopioid | C9: int_check | D9: check | E9: 0.1 | F9: Assume could reach higher % if overdose risk increase
A10: PWID_meth | B10: injection_overdose_nonopioid | C10: int_nal | D10: naloxone | E10: 0.63 | F10: 90% among methamphetamine users who also use heroin
A11: PWID_meth | B11: injection_overdose_nonopioid | C11: int_dcr | D11: medicalised | E11: 0.3 | F11: Assumption
A12: PWID_meth | B12: injection_overdose_nonopioid | C12: int_dcr | D12: peerled | E12: 0.6 | F12: Assume can reach double coverage with two sites
A13: PWID_meth | B13: injection_overdose_nonopioid | C13: int_techno | D13: techno | E13: 0 | F13: Assume only rolled out for opioid users. (Alternative, 47% based on % who used alone at last injection [IDRS ACT 2023, data request received 3/12/2024])
... A29: noninjectdrug_nonopioid | B29: noninjectdrug_nonopioidoverdose | C29: int_techno | D29: techno | E29: 0 | F29: Assume only relevant for people injecting opioids
